[2025-06-10T19:43:35.914+0000] {taskinstance.py:1956} INFO - Dependencies all met for dep_context=non-requeueable deps ti=<TaskInstance: movie_etl_pipeline.extract_data manual__2025-06-10T19:41:16.507438+00:00 [queued]>
[2025-06-10T19:43:35.923+0000] {taskinstance.py:1956} INFO - Dependencies all met for dep_context=requeueable deps ti=<TaskInstance: movie_etl_pipeline.extract_data manual__2025-06-10T19:41:16.507438+00:00 [queued]>
[2025-06-10T19:43:35.924+0000] {taskinstance.py:2170} INFO - Starting attempt 1 of 1
[2025-06-10T19:43:35.940+0000] {taskinstance.py:2191} INFO - Executing <Task(PythonOperator): extract_data> on 2025-06-10 19:41:16.507438+00:00
[2025-06-10T19:43:35.946+0000] {standard_task_runner.py:60} INFO - Started process 238 to run task
[2025-06-10T19:43:35.950+0000] {standard_task_runner.py:87} INFO - Running: ['***', 'tasks', 'run', 'movie_etl_pipeline', 'extract_data', 'manual__2025-06-10T19:41:16.507438+00:00', '--job-id', '3', '--raw', '--subdir', 'DAGS_FOLDER/movie_etl_pipeline.py', '--cfg-path', '/tmp/tmpkpsvtgdb']
[2025-06-10T19:43:35.954+0000] {standard_task_runner.py:88} INFO - Job 3: Subtask extract_data
[2025-06-10T19:43:35.974+0000] {logging_mixin.py:188} WARNING - /home/***/.local/lib/python3.11/site-packages/***/settings.py:194 DeprecationWarning: The sql_alchemy_conn option in [core] has been moved to the sql_alchemy_conn option in [database] - the old setting has been used, but please update your config.
[2025-06-10T19:43:36.026+0000] {task_command.py:423} INFO - Running <TaskInstance: movie_etl_pipeline.extract_data manual__2025-06-10T19:41:16.507438+00:00 [running]> on host 63384fd990fc
[2025-06-10T19:43:36.149+0000] {taskinstance.py:2480} INFO - Exporting env vars: AIRFLOW_CTX_DAG_OWNER='***' AIRFLOW_CTX_DAG_ID='movie_etl_pipeline' AIRFLOW_CTX_TASK_ID='extract_data' AIRFLOW_CTX_EXECUTION_DATE='2025-06-10T19:41:16.507438+00:00' AIRFLOW_CTX_TRY_NUMBER='1' AIRFLOW_CTX_DAG_RUN_ID='manual__2025-06-10T19:41:16.507438+00:00'
[2025-06-10T19:43:36.152+0000] {logging_mixin.py:188} INFO - Lecture de movies.csv...
[2025-06-10T19:43:36.156+0000] {taskinstance.py:2698} ERROR - Task failed with exception
Traceback (most recent call last):
  File "/home/airflow/.local/lib/python3.11/site-packages/airflow/models/taskinstance.py", line 433, in _execute_task
    result = execute_callable(context=context, **execute_callable_kwargs)
             ^^^^^^^^^^^^^^^^^^^^^^^^^^^^^^^^^^^^^^^^^^^^^^^^^^^^^^^^^^^^
  File "/home/airflow/.local/lib/python3.11/site-packages/airflow/operators/python.py", line 199, in execute
    return_value = self.execute_callable()
                   ^^^^^^^^^^^^^^^^^^^^^^^
  File "/home/airflow/.local/lib/python3.11/site-packages/airflow/operators/python.py", line 216, in execute_callable
    return self.python_callable(*self.op_args, **self.op_kwargs)
           ^^^^^^^^^^^^^^^^^^^^^^^^^^^^^^^^^^^^^^^^^^^^^^^^^^^^^
  File "/opt/airflow/dags/movie_etl_pipeline.py", line 18, in extract_data
    df = pd.read_csv('/opt/airflow/data/raw/ml-latest-small/movies.csv')
         ^^^^^^^^^^^^^^^^^^^^^^^^^^^^^^^^^^^^^^^^^^^^^^^^^^^^^^^^^^^^^^^
  File "/home/airflow/.local/lib/python3.11/site-packages/pandas/io/parsers/readers.py", line 948, in read_csv
    return _read(filepath_or_buffer, kwds)
           ^^^^^^^^^^^^^^^^^^^^^^^^^^^^^^^
  File "/home/airflow/.local/lib/python3.11/site-packages/pandas/io/parsers/readers.py", line 611, in _read
    parser = TextFileReader(filepath_or_buffer, **kwds)
             ^^^^^^^^^^^^^^^^^^^^^^^^^^^^^^^^^^^^^^^^^^
  File "/home/airflow/.local/lib/python3.11/site-packages/pandas/io/parsers/readers.py", line 1448, in __init__
    self._engine = self._make_engine(f, self.engine)
                   ^^^^^^^^^^^^^^^^^^^^^^^^^^^^^^^^^
  File "/home/airflow/.local/lib/python3.11/site-packages/pandas/io/parsers/readers.py", line 1705, in _make_engine
    self.handles = get_handle(
                   ^^^^^^^^^^^
  File "/home/airflow/.local/lib/python3.11/site-packages/pandas/io/common.py", line 863, in get_handle
    handle = open(
             ^^^^^
FileNotFoundError: [Errno 2] No such file or directory: '/opt/airflow/data/raw/ml-latest-small/movies.csv'
[2025-06-10T19:43:36.174+0000] {taskinstance.py:1138} INFO - Marking task as FAILED. dag_id=movie_etl_pipeline, task_id=extract_data, execution_date=20250610T194116, start_date=20250610T194335, end_date=20250610T194336
[2025-06-10T19:43:36.190+0000] {standard_task_runner.py:107} ERROR - Failed to execute job 3 for task extract_data ([Errno 2] No such file or directory: '/opt/airflow/data/raw/ml-latest-small/movies.csv'; 238)
[2025-06-10T19:43:36.209+0000] {local_task_job_runner.py:234} INFO - Task exited with return code 1
[2025-06-10T19:43:36.235+0000] {taskinstance.py:3280} INFO - 0 downstream tasks scheduled from follow-on schedule check
