[2025-06-10T22:09:15.654+0000] {taskinstance.py:1956} INFO - Dependencies all met for dep_context=non-requeueable deps ti=<TaskInstance: movie_etl_pipeline.extract_data manual__2025-06-10T22:09:14.770401+00:00 [queued]>
[2025-06-10T22:09:15.662+0000] {taskinstance.py:1956} INFO - Dependencies all met for dep_context=requeueable deps ti=<TaskInstance: movie_etl_pipeline.extract_data manual__2025-06-10T22:09:14.770401+00:00 [queued]>
[2025-06-10T22:09:15.663+0000] {taskinstance.py:2170} INFO - Starting attempt 1 of 1
[2025-06-10T22:09:15.679+0000] {taskinstance.py:2191} INFO - Executing <Task(PythonOperator): extract_data> on 2025-06-10 22:09:14.770401+00:00
[2025-06-10T22:09:15.686+0000] {standard_task_runner.py:60} INFO - Started process 227 to run task
[2025-06-10T22:09:15.688+0000] {standard_task_runner.py:87} INFO - Running: ['***', 'tasks', 'run', 'movie_etl_pipeline', 'extract_data', 'manual__2025-06-10T22:09:14.770401+00:00', '--job-id', '7', '--raw', '--subdir', 'DAGS_FOLDER/movie_etl_pipeline.py', '--cfg-path', '/tmp/tmpypat0os9']
[2025-06-10T22:09:15.691+0000] {standard_task_runner.py:88} INFO - Job 7: Subtask extract_data
[2025-06-10T22:09:15.707+0000] {logging_mixin.py:188} WARNING - /home/***/.local/lib/python3.11/site-packages/***/settings.py:194 DeprecationWarning: The sql_alchemy_conn option in [core] has been moved to the sql_alchemy_conn option in [database] - the old setting has been used, but please update your config.
[2025-06-10T22:09:15.739+0000] {task_command.py:423} INFO - Running <TaskInstance: movie_etl_pipeline.extract_data manual__2025-06-10T22:09:14.770401+00:00 [running]> on host 2bb47da558a0
[2025-06-10T22:09:15.811+0000] {taskinstance.py:2480} INFO - Exporting env vars: AIRFLOW_CTX_DAG_OWNER='***' AIRFLOW_CTX_DAG_ID='movie_etl_pipeline' AIRFLOW_CTX_TASK_ID='extract_data' AIRFLOW_CTX_EXECUTION_DATE='2025-06-10T22:09:14.770401+00:00' AIRFLOW_CTX_TRY_NUMBER='1' AIRFLOW_CTX_DAG_RUN_ID='manual__2025-06-10T22:09:14.770401+00:00'
[2025-06-10T22:09:15.813+0000] {logging_mixin.py:188} INFO - üîé Lecture de : /opt/***/dags/data/raw/movies.csv
[2025-06-10T22:09:15.815+0000] {taskinstance.py:2698} ERROR - Task failed with exception
Traceback (most recent call last):
  File "/home/airflow/.local/lib/python3.11/site-packages/airflow/models/taskinstance.py", line 433, in _execute_task
    result = execute_callable(context=context, **execute_callable_kwargs)
             ^^^^^^^^^^^^^^^^^^^^^^^^^^^^^^^^^^^^^^^^^^^^^^^^^^^^^^^^^^^^
  File "/home/airflow/.local/lib/python3.11/site-packages/airflow/operators/python.py", line 199, in execute
    return_value = self.execute_callable()
                   ^^^^^^^^^^^^^^^^^^^^^^^
  File "/home/airflow/.local/lib/python3.11/site-packages/airflow/operators/python.py", line 216, in execute_callable
    return self.python_callable(*self.op_args, **self.op_kwargs)
           ^^^^^^^^^^^^^^^^^^^^^^^^^^^^^^^^^^^^^^^^^^^^^^^^^^^^^
  File "/opt/airflow/dags/movie_etl_pipeline.py", line 13, in extract_data
    raise FileNotFoundError(f"‚ùå Le fichier {filepath} est introuvable dans le conteneur Airflow.")
FileNotFoundError: ‚ùå Le fichier /opt/***/dags/data/raw/movies.csv est introuvable dans le conteneur Airflow.
[2025-06-10T22:09:15.829+0000] {taskinstance.py:1138} INFO - Marking task as FAILED. dag_id=movie_etl_pipeline, task_id=extract_data, execution_date=20250610T220914, start_date=20250610T220915, end_date=20250610T220915
[2025-06-10T22:09:15.843+0000] {standard_task_runner.py:107} ERROR - Failed to execute job 7 for task extract_data (‚ùå Le fichier /opt/***/dags/data/raw/movies.csv est introuvable dans le conteneur Airflow.; 227)
[2025-06-10T22:09:15.863+0000] {local_task_job_runner.py:234} INFO - Task exited with return code 1
[2025-06-10T22:09:15.884+0000] {taskinstance.py:3280} INFO - 0 downstream tasks scheduled from follow-on schedule check
