[2025-06-10T23:45:45.426+0000] {taskinstance.py:1956} INFO - Dependencies all met for dep_context=non-requeueable deps ti=<TaskInstance: movie_ml_pipeline.fetch_data_from_postgres manual__2025-06-10T23:45:43.624763+00:00 [queued]>
[2025-06-10T23:45:45.435+0000] {taskinstance.py:1956} INFO - Dependencies all met for dep_context=requeueable deps ti=<TaskInstance: movie_ml_pipeline.fetch_data_from_postgres manual__2025-06-10T23:45:43.624763+00:00 [queued]>
[2025-06-10T23:45:45.436+0000] {taskinstance.py:2170} INFO - Starting attempt 1 of 1
[2025-06-10T23:45:45.452+0000] {taskinstance.py:2191} INFO - Executing <Task(PythonOperator): fetch_data_from_postgres> on 2025-06-10 23:45:43.624763+00:00
[2025-06-10T23:45:45.460+0000] {standard_task_runner.py:60} INFO - Started process 313 to run task
[2025-06-10T23:45:45.464+0000] {standard_task_runner.py:87} INFO - Running: ['***', 'tasks', 'run', 'movie_ml_pipeline', 'fetch_data_from_postgres', 'manual__2025-06-10T23:45:43.624763+00:00', '--job-id', '17', '--raw', '--subdir', 'DAGS_FOLDER/ml_pipeline.py', '--cfg-path', '/tmp/tmpq38f9yzc']
[2025-06-10T23:45:45.467+0000] {standard_task_runner.py:88} INFO - Job 17: Subtask fetch_data_from_postgres
[2025-06-10T23:45:45.485+0000] {logging_mixin.py:188} WARNING - /home/***/.local/lib/python3.11/site-packages/***/settings.py:194 DeprecationWarning: The sql_alchemy_conn option in [core] has been moved to the sql_alchemy_conn option in [database] - the old setting has been used, but please update your config.
[2025-06-10T23:45:45.531+0000] {task_command.py:423} INFO - Running <TaskInstance: movie_ml_pipeline.fetch_data_from_postgres manual__2025-06-10T23:45:43.624763+00:00 [running]> on host 3dd2cd0f60a8
[2025-06-10T23:45:45.623+0000] {taskinstance.py:2480} INFO - Exporting env vars: AIRFLOW_CTX_DAG_OWNER='***' AIRFLOW_CTX_DAG_ID='movie_ml_pipeline' AIRFLOW_CTX_TASK_ID='fetch_data_from_postgres' AIRFLOW_CTX_EXECUTION_DATE='2025-06-10T23:45:43.624763+00:00' AIRFLOW_CTX_TRY_NUMBER='1' AIRFLOW_CTX_DAG_RUN_ID='manual__2025-06-10T23:45:43.624763+00:00'
[2025-06-10T23:45:45.669+0000] {logging_mixin.py:188} WARNING - /opt/***/dags/ml_pipeline.py:15 UserWarning: pandas only supports SQLAlchemy connectable (engine/connection) or database string URI or sqlite3 DBAPI2 connection. Other DBAPI2 objects are not tested. Please consider using SQLAlchemy.
[2025-06-10T23:45:45.734+0000] {logging_mixin.py:188} WARNING - /opt/***/dags/ml_pipeline.py:16 UserWarning: pandas only supports SQLAlchemy connectable (engine/connection) or database string URI or sqlite3 DBAPI2 connection. Other DBAPI2 objects are not tested. Please consider using SQLAlchemy.
[2025-06-10T23:45:46.013+0000] {taskinstance.py:2698} ERROR - Task failed with exception
Traceback (most recent call last):
  File "/home/airflow/.local/lib/python3.11/site-packages/airflow/models/taskinstance.py", line 433, in _execute_task
    result = execute_callable(context=context, **execute_callable_kwargs)
             ^^^^^^^^^^^^^^^^^^^^^^^^^^^^^^^^^^^^^^^^^^^^^^^^^^^^^^^^^^^^
  File "/home/airflow/.local/lib/python3.11/site-packages/airflow/operators/python.py", line 199, in execute
    return_value = self.execute_callable()
                   ^^^^^^^^^^^^^^^^^^^^^^^
  File "/home/airflow/.local/lib/python3.11/site-packages/airflow/operators/python.py", line 216, in execute_callable
    return self.python_callable(*self.op_args, **self.op_kwargs)
           ^^^^^^^^^^^^^^^^^^^^^^^^^^^^^^^^^^^^^^^^^^^^^^^^^^^^^
  File "/opt/airflow/dags/ml_pipeline.py", line 19, in fetch_data
    movies.to_csv("/opt/airflow/dags/data/ml/movies.csv", index=False)
  File "/home/airflow/.local/lib/python3.11/site-packages/pandas/core/generic.py", line 3902, in to_csv
    return DataFrameRenderer(formatter).to_csv(
           ^^^^^^^^^^^^^^^^^^^^^^^^^^^^^^^^^^^^
  File "/home/airflow/.local/lib/python3.11/site-packages/pandas/io/formats/format.py", line 1152, in to_csv
    csv_formatter.save()
  File "/home/airflow/.local/lib/python3.11/site-packages/pandas/io/formats/csvs.py", line 247, in save
    with get_handle(
         ^^^^^^^^^^^
  File "/home/airflow/.local/lib/python3.11/site-packages/pandas/io/common.py", line 739, in get_handle
    check_parent_directory(str(handle))
  File "/home/airflow/.local/lib/python3.11/site-packages/pandas/io/common.py", line 604, in check_parent_directory
    raise OSError(rf"Cannot save file into a non-existent directory: '{parent}'")
OSError: Cannot save file into a non-existent directory: '/opt/***/dags/data/ml'
[2025-06-10T23:45:46.042+0000] {taskinstance.py:1138} INFO - Marking task as FAILED. dag_id=movie_ml_pipeline, task_id=fetch_data_from_postgres, execution_date=20250610T234543, start_date=20250610T234545, end_date=20250610T234546
[2025-06-10T23:45:46.062+0000] {standard_task_runner.py:107} ERROR - Failed to execute job 17 for task fetch_data_from_postgres (Cannot save file into a non-existent directory: '/opt/***/dags/data/ml'; 313)
[2025-06-10T23:45:46.080+0000] {local_task_job_runner.py:234} INFO - Task exited with return code 1
[2025-06-10T23:45:46.104+0000] {taskinstance.py:3280} INFO - 0 downstream tasks scheduled from follow-on schedule check
